Workbook

Sheet Read Me
B2: Bideo — SEO, AEO & ASO Master Plan
B3: Goal: rank on Google & Bing, get mentioned by AI assistants, and rank in the Play Store — without breaking the working app or website.
B5: What the 3 words mean
B6: SEO — Search Engine Optimisation: making bideo.in appear in Google/Bing results.
B7: AEO — Answer Engine Optimisation: getting ChatGPT, Perplexity, Gemini, Copilot and Google AI Overviews to mention Bideo in their answers.
B8: ASO — App Store Optimisation: ranking in Play Store (and App Store) search and turning store visitors into installs.
B9: ⚠ URGENT: the public API exposes creators' phone numbers & emails and private videos — fix tab 0 before any SEO work.
B10: Why bideo.in isn't on Google yet (main reasons found)
B11: 1. The site is new (homepage dated 4 Oct 2026) and probably not submitted to Google Search Console yet → task F01–F02.
B12: 2. The homepage has no text in its HTML — everything is loaded by JavaScript → T01.
B13: 3. robots.txt blocks /api/, where the pages get their content — keep it blocked and fix via server rendering → T01/T02.
B14: 4. Video pages push Android visitors (including Google's mobile crawler) to the app → T05.
... B17: Progress
B18: Tab | C18: Tasks | D18: Done | E18: Must left | F18: High-risk left | G18: % done | H18: What it covers
B19: 0. Security (Fix First) | C19: =COUNTA('0. Security (Fix First)'!A5:A14)-COUNTIF('0. Security (Fix First)'!A5:A14,"* *") -> 8 | D19: =COUNTIF('0. Security (Fix First)'!L5:L14,"Done")+COUNTIF('0. Security (Fix First)'!L5:L14,"Not needed") -> 0 | E19: =COUNTIFS('0. Security (Fix First)'!G5:G14,"Must",'0. Security (Fix First)'!L5:L14,"<>Done",'0. Security (Fix First)'!L5:L14,"<>Not needed") -> 4 | F19: =COUNTIFS('0. Security (Fix First)'!H5:H14,"High",'0. Security (Fix First)'!L5:L14,"<>Done",'0. Security (Fix First)'!L5:L14,"<>Not needed")+COUNTIFS('0. Security (Fix First)'!H5:H14,"Medium",'0. Security (Fix First)'!L5:L14,"<>Done",'0. Security (Fix First)'!L5:L14,"<>Not needed") -> 3 | G19: =IF(C19>0,D19/C19,0) -> 0 | H19: Public API leaks phone/email, private videos, earnings — fix first
B20: 1. Foundations | C20: =COUNTA('1. Foundations'!A5:A15)-COUNTIF('1. Foundations'!A5:A15,"* *") -> 9 | D20: =COUNTIF('1. Foundations'!L5:L15,"Done")+COUNTIF('1. Foundations'!L5:L15,"Not needed") -> 0 | E20: =COUNTIFS('1. Foundations'!G5:G15,"Must",'1. Foundations'!L5:L15,"<>Done",'1. Foundations'!L5:L15,"<>Not needed") -> 6 | F20: =COUNTIFS('1. Foundations'!H5:H15,"High",'1. Foundations'!L5:L15,"<>Done",'1. Foundations'!L5:L15,"<>Not needed")+COUNTIFS('1. Foundations'!H5:H15,"Medium",'1. Foundations'!L5:L15,"<>Done",'1. Foundations'!L5:L15,"<>Not needed") -> 0 | G20: =IF(C20>0,D20/C20,0) -> 0 | H20: Search Console, Bing, analytics, baseline, staging, backups
B21: 2. Technical SEO | C21: =COUNTA('2. Technical SEO'!A5:A21)-COUNTIF('2. Technical SEO'!A5:A21,"* *") -> 15 | D21: =COUNTIF('2. Technical SEO'!L5:L21,"Done")+COUNTIF('2. Technical SEO'!L5:L21,"Not needed") -> 0 | E21: =COUNTIFS('2. Technical SEO'!G5:G21,"Must",'2. Technical SEO'!L5:L21,"<>Done",'2. Technical SEO'!L5:L21,"<>Not needed") -> 8 | F21: =COUNTIFS('2. Technical SEO'!H5:H21,"High",'2. Technical SEO'!L5:L21,"<>Done",'2. Technical SEO'!L5:L21,"<>Not needed")+COUNTIFS('2. Technical SEO'!H5:H21,"Medium",'2. Technical SEO'!L5:L21,"<>Done",'2. Technical SEO'!L5:L21,"<>Not needed") -> 6 | G21: =IF(C21>0,D21/C21,0) -> 0 | H21: Rendering, robots, redirects, 404s, speed, sitemap, canonicals
B22: 3. Pages & Content | C22: =COUNTA('3. Pages & Content'!A5:A16)-COUNTIF('3. Pages & Content'!A5:A16,"* *") -> 10 | D22: =COUNTIF('3. Pages & Content'!L5:L16,"Done")+COUNTIF('3. Pages & Content'!L5:L16,"Not needed") -> 0 | E22: =COUNTIFS('3. Pages & Content'!G5:G16,"Must",'3. Pages & Content'!L5:L16,"<>Done",'3. Pages & Content'!L5:L16,"<>Not needed") -> 5 | F22: =COUNTIFS('3. Pages & Content'!H5:H16,"High",'3. Pages & Content'!L5:L16,"<>Done",'3. Pages & Content'!L5:L16,"<>Not needed")+COUNTIFS('3. Pages & Content'!H5:H16,"Medium",'3. Pages & Content'!L5:L16,"<>Done",'3. Pages & Content'!L5:L16,"<>Not needed") -> 1 | G22: =IF(C22>0,D22/C22,0) -> 0 | H22: Homepage, titles, static & policy pages, hub pages, blog, brand text
B23: 4. Video & Creator Pages | C23: =COUNTA('4. Video & Creator Pages'!A5:A17)-COUNTIF('4. Video & Creator Pages'!A5:A17,"* *") -> 11 | D23: =COUNTIF('4. Video & Creator Pages'!L5:L17,"Done")+COUNTIF('4. Video & Creator Pages'!L5:L17,"Not needed") -> 0 | E23: =COUNTIFS('4. Video & Creator Pages'!G5:G17,"Must",'4. Video & Creator Pages'!L5:L17,"<>Done",'4. Video & Creator Pages'!L5:L17,"<>Not needed") -> 6 | F23: =COUNTIFS('4. Video & Creator Pages'!H5:H17,"High",'4. Video & Creator Pages'!L5:L17,"<>Done",'4. Video & Creator Pages'!L5:L17,"<>Not needed")+COUNTIFS('4. Video & Creator Pages'!H5:H17,"Medium",'4. Video & Creator Pages'!L5:L17,"<>Done",'4. Video & Creator Pages'!L5:L17,"<>Not needed") -> 3 | G23: =IF(C23>0,D23/C23,0) -> 0 | H23: VideoObject schema, visible text, web player, titles, media domain
B24: 5. AEO (AI Search) | C24: =COUNTA('5. AEO (AI Search)'!A5:A17)-COUNTIF('5. AEO (AI Search)'!A5:A17,"* *") -> 11 | D24: =COUNTIF('5. AEO (AI Search)'!L5:L17,"Done")+COUNTIF('5. AEO (AI Search)'!L5:L17,"Not needed") -> 0 | E24: =COUNTIFS('5. AEO (AI Search)'!G5:G17,"Must",'5. AEO (AI Search)'!L5:L17,"<>Done",'5. AEO (AI Search)'!L5:L17,"<>Not needed") -> 7 | F24: =COUNTIFS('5. AEO (AI Search)'!H5:H17,"High",'5. AEO (AI Search)'!L5:L17,"<>Done",'5. AEO (AI Search)'!L5:L17,"<>Not needed")+COUNTIFS('5. AEO (AI Search)'!H5:H17,"Medium",'5. AEO (AI Search)'!L5:L17,"<>Done",'5. AEO (AI Search)'!L5:L17,"<>Not needed") -> 1 | G24: =IF(C24>0,D24/C24,0) -> 0 | H24: AI crawlers, 'What is Bideo', FAQ, Organization schema, consistency
B25: 6. ASO - Google Play | C25: =COUNTA('6. ASO - Google Play'!A5:A26)-COUNTIF('6. ASO - Google Play'!A5:A26,"* *") -> 18 | D25: =COUNTIF('6. ASO - Google Play'!L5:L26,"Done")+COUNTIF('6. ASO - Google Play'!L5:L26,"Not needed") -> 0 | E25: =COUNTIFS('6. ASO - Google Play'!G5:G26,"Must",'6. ASO - Google Play'!L5:L26,"<>Done",'6. ASO - Google Play'!L5:L26,"<>Not needed") -> 9 | F25: =COUNTIFS('6. ASO - Google Play'!H5:H26,"High",'6. ASO - Google Play'!L5:L26,"<>Done",'6. ASO - Google Play'!L5:L26,"<>Not needed")+COUNTIFS('6. ASO - Google Play'!H5:H26,"Medium",'6. ASO - Google Play'!L5:L26,"<>Done",'6. ASO - Google Play'!L5:L26,"<>Not needed") -> 0 | G25: =IF(C25>0,D25/C25,0) -> 0 | H25: Keywords, title, descriptions, graphics, translations, tests, ratings, vitals
B26: 7. ASO - App Store | C26: =COUNTA('7. ASO - App Store'!A5:A12)-COUNTIF('7. ASO - App Store'!A5:A12,"* *") -> 7 | D26: =COUNTIF('7. ASO - App Store'!L5:L12,"Done")+COUNTIF('7. ASO - App Store'!L5:L12,"Not needed") -> 0 | E26: =COUNTIFS('7. ASO - App Store'!G5:G12,"Must",'7. ASO - App Store'!L5:L12,"<>Done",'7. ASO - App Store'!L5:L12,"<>Not needed") -> 4 | F26: =COUNTIFS('7. ASO - App Store'!H5:H12,"High",'7. ASO - App Store'!L5:L12,"<>Done",'7. ASO - App Store'!L5:L12,"<>Not needed")+COUNTIFS('7. ASO - App Store'!H5:H12,"Medium",'7. ASO - App Store'!L5:L12,"<>Done",'7. ASO - App Store'!L5:L12,"<>Not needed") -> 0 | G26: =IF(C26>0,D26/C26,0) -> 0 | H26: Only if/when an iPhone app launches
B27: 8. Inside the App | C27: =COUNTA('8. Inside the App'!A5:A18)-COUNTIF('8. Inside the App'!A5:A18,"* *") -> 11 | D27: =COUNTIF('8. Inside the App'!L5:L18,"Done")+COUNTIF('8. Inside the App'!L5:L18,"Not needed") -> 0 | E27: =COUNTIFS('8. Inside the App'!G5:G18,"Must",'8. Inside the App'!L5:L18,"<>Done",'8. Inside the App'!L5:L18,"<>Not needed") -> 5 | F27: =COUNTIFS('8. Inside the App'!H5:H18,"High",'8. Inside the App'!L5:L18,"<>Done",'8. Inside the App'!L5:L18,"<>Not needed")+COUNTIFS('8. Inside the App'!H5:H18,"Medium",'8. Inside the App'!L5:L18,"<>Done",'8. Inside the App'!L5:L18,"<>Not needed") -> 0 | G27: =IF(C27>0,D27/C27,0) -> 0 | H27: Share links, App Links, upload form, review prompt, stability
B28: 9. Authority | C28: =COUNTA('9. Authority'!A5:A12)-COUNTIF('9. Authority'!A5:A12,"* *") -> 7 | D28: =COUNTIF('9. Authority'!L5:L12,"Done")+COUNTIF('9. Authority'!L5:L12,"Not needed") -> 0 | E28: =COUNTIFS('9. Authority'!G5:G12,"Must",'9. Authority'!L5:L12,"<>Done",'9. Authority'!L5:L12,"<>Not needed") -> 2 | F28: =COUNTIFS('9. Authority'!H5:H12,"High",'9. Authority'!L5:L12,"<>Done",'9. Authority'!L5:L12,"<>Not needed")+COUNTIFS('9. Authority'!H5:H12,"Medium",'9. Authority'!L5:L12,"<>Done",'9. Authority'!L5:L12,"<>Not needed") -> 0 | G28: =IF(C28>0,D28/C28,0) -> 0 | H28: Social profiles, directories, PR, creators' links, what never to do
B29: 10. Safe Release Rules | C29: =COUNTA('10. Safe Release Rules'!A5:A15)-COUNTIF('10. Safe Release Rules'!A5:A15,"* *") -> 10 | D29: =COUNTIF('10. Safe Release Rules'!L5:L15,"Done")+COUNTIF('10. Safe Release Rules'!L5:L15,"Not needed") -> 0 | E29: =COUNTIFS('10. Safe Release Rules'!G5:G15,"Must",'10. Safe Release Rules'!L5:L15,"<>Done",'10. Safe Release Rules'!L5:L15,"<>Not needed") -> 10 | F29: =COUNTIFS('10. Safe Release Rules'!H5:H15,"High",'10. Safe Release Rules'!L5:L15,"<>Done",'10. Safe Release Rules'!L5:L15,"<>Not needed")+COUNTIFS('10. Safe Release Rules'!H5:H15,"Medium",'10. Safe Release Rules'!L5:L15,"<>Done",'10. Safe Release Rules'!L5:L15,"<>Not needed") -> 0 | G29: =IF(C29>0,D29/C29,0) -> 0 | H29: How to deploy every change without breaking anything
B30: TOTAL | C30: =SUM(C19:C29) -> 117 | D30: =SUM(D19:D29) -> 0 | E30: =SUM(E19:E29) -> 66 | F30: =SUM(F19:F29) -> 14 | G30: =IF(C30>0,D30/C30,0) -> 0
F31: (Medium + High risk)
B33: Suggested order (about 8–10 weeks)
B34: Day 1 | C34: SECURITY (tab 0): remove phone/email from API, block private videos for logged-out users
B35: Week 1 | C35: Foundations (tab 1) + quick technical fixes with low risk: T02 robots, T03 www redirect, T07 compression, T06 policy pages
B36: Weeks 2–4 | C36: Rendering (T01), video page redirect (T05), 404s (T04), video schema & text (tab 4), homepage & pages (tab 3)
B37: Weeks 2–3 (in parallel) | C37: ASO (tab 6): keyword research → title, short/full description → screenshots → experiments
B38: Weeks 3–6 | C38: Inside the App (tab 8): upload form, share links, review prompt; AEO (tab 5)
B39: Ongoing | C39: Authority (tab 9), Monthly Tracker (tab 11); weekly Search Console check
B41: How to use this file
B42: • Each task row: Why it matters → How to do it → Current status (what I saw on 7 Oct) → Break risk → How to do it safely.
B43: • Fill the yellow cells: Owner and Status (Not started / In progress / Done / Blocked / Not needed). Progress above updates automatically.
B44: • Priority: Must = core, do first · Should = important, next · Nice = when time allows.
B45: • Break risk: Low = can't affect the working app · Medium = test on staging first · High = plan carefully + rollback ready.
B46: • Before any Medium-risk task, read tab 10 'Safe Release Rules'.
...

Sheet Audit Findings
A1: What I found on bideo.in and the Play Store (checked 7 Oct 2026)
A2: Checked from outside, the way search engines see it (no access to code or Search Console). Fix the red items first.
A4: # | B4: Check | C4: Result | D4: What we saw | E4: Why it matters | F4: Fix in task
A5: 1 | B5: API: creators' phone & email | C5: PROBLEM | D5: GET /api/videos (no login) returns owner.phone (54/54) and owner.email (31/54) on page 1; 42,592 videos over 852 pages. | E5: Anyone can collect every creator's contact details. Privacy + DPDP Act risk. | F5: X01
A6: 2 | B6: API: private videos | C6: PROBLEM | D6: /api/videos?visibility=private returned 28 private videos without login. | E6: Private content is not private. | F6: X02
A7: 3 | B7: API: earnings & likes | C7: PROBLEM | D7: revenue, pendingRevenue and full likes lists (user IDs) are public. | E7: Exposes creator earnings and user activity. | F7: X04
A8: 4 | B8: API: bulk copying | C8: CHECK | D8: ?limit=500 returns 104 per page; rate limit 10,000 requests / 15 min per IP. | E8: Makes copying the whole catalogue easy. | F8: X05
A9: 5 | B9: Homepage content in HTML | C9: PROBLEM | D9: Homepage HTML is only a title, a one-line description and an empty <div id="root">. All text comes from JavaScript. | E9: Google may see a blank page; Bing and most AI crawlers definitely do. | F9: T01
A10: 6 | B10: robots.txt vs website data | C10: PROBLEM | D10: robots.txt has 'Disallow: /api/' but the website loads its videos/users/categories from /api/. | E10: Google is not allowed to fetch the data it needs to render the pages → empty pages. | F10: T02
A11: 7 | B11: www version | C11: PROBLEM | D11: https://www.bideo.in/ returns 200 (duplicate site) instead of redirecting. | E11: Duplicate content; ranking signals split. | F11: T03
A12: 8 | B12: Unknown URLs | C12: PROBLEM | D12: Any made-up URL returns 200 with the homepage (soft 404). | E12: Wasted crawling; junk URLs can get indexed. | F12: T04
A13: 9 | B13: Video page behaviour | C13: PROBLEM | D13: Video pages auto-redirect Android visitors to the app/Play Store via a script. | E13: Google's mobile crawler identifies as Android → may be sent away before reading the page. | F13: T05
A14: 10 | B14: /privacy, /terms | C14: PROBLEM | D14: Return exactly the same HTML as the homepage (content only via JS). | E14: Play/ads reviewers and crawlers see blank policy pages. | F14: T06
A15: 11 | B15: Compression | C15: PROBLEM | D15: Main JS file (~564 KB) is sent without gzip/brotli. | E15: Slow on mobile networks; speed affects rankings and bounce. | F15: T07
A16: 12 | B16: Sitemap size | C16: CHECK | D16: Sitemap lists exactly 1,000 video, 200 creator and 200 post URLs. | E16: Looks capped — other pages may never be found. | F16: T08
... A31: 27 | B31: Google indexing | C31: UNKNOWN | D31: Can't be checked from outside. You said the site doesn't show on Google; homepage file dated 4 Oct 2026 (new). | E31: Verify in Search Console. | F31: F01, F02

Sheet 0. Security (Fix First)
A1: 0. Security — fix FIRST: the public API leaks personal data
A2: Found while checking SEO on 7 Oct 2026. These are more urgent than any SEO task. Values were counted, not copied.
A4: ID | B4: Area | C4: Task | D4: Why it matters | E4: How to do it | F4: Current status (checked 7 Oct 2026) | G4: Priority | H4: Break risk | I4: How to do it safely (don't break anything) | J4: Done when… | K4: Owner | L4: Status
A5: A. Fix TODAY — personal data is public
A6: X01 | B6: API | C6: Remove creators' phone and email from public API responses | D6: GET /api/videos returns each creator's phone number and email to anyone, without login. With 42,592 videos over 852 pages, a script can collect every creator's contact details in minutes. Spam/scam risk for creators and a legal risk under India's DPDP Act. | E6: In the backend query that loads the video owner (e.g. Mongoose .populate('owner', ...)), select ONLY: _id, name, avatar, channelName, isVerified, followersCount. Apply the same to every public endpoint that includes user objects (comments, search, creator pages, trending). | F6: PROBLEM — owner.phone present for 54/54 and owner.email for 31/54 creators on page 1 (counted 7 Oct; values not copied). | G6: Must | H6: Low | I6: The app and website should never show other people's phone/email, so removing them changes nothing visible. Search the app/web code for 'owner.phone' / 'owner.email' first to be sure. | J6: curl /api/videos shows no phone or email fields | L6: Not started
A7: X02 | B7: API | C7: Logged-out users must never get private videos | D7: Adding ?visibility=private to /api/videos returns private videos. Creators who set a video private expect nobody to see it. | E7: On the server, force visibility='public' for public listing endpoints and ignore the visibility parameter unless the logged-in user is the owner (for their own 'My videos' list). | F7: PROBLEM — /api/videos?visibility=private returned 28 private videos without login. | G7: Must | H7: Low | I7: Test the creator's own 'My videos' screen still shows their private videos after the change. | J7: ?visibility=private without login returns only public videos (or 403) | L7: Not started
A8: X03 | B8: API | C8: Audit every other public endpoint the same way | D8: The same mistake (returning the full database record) is usually repeated in several places. | E8: Check without logging in: /api/videos/<id>, /api/users/<id>, comments, search, categories, ads, trending, creator profile. Look for phone, email, password/hash, tokens, OTP, revenue, device IDs, addresses. | F8: /api/users (list) correctly returns 401. Others not checked. | G8: Must | H8: Low | I8: Read-only checking. | J8: Checklist of endpoints with 'safe' confirmed for each | L8: Not started
A9: B. Fix THIS WEEK
A10: X04 | B10: API | C10: Return a fixed, safe list of fields (allow-list) | D10: Sending the whole database record means every new column (e.g. a future bank detail) leaks automatically. | E10: For each public endpoint define exactly which fields go out. Remove from public video responses: revenue, pendingRevenue, likes (send likesCount), dislikes (send count), original/compressed sizes, boostType, boostExpiresAt, __v. | F10: PROBLEM — revenue/pendingRevenue and full likes lists (user IDs) are public. | G10: Must | H10: Medium | I10: If the app reads 'likes' to know whether the current user liked a video, replace it with a 'likedByMe' true/false field — release the app update BEFORE removing the old field from the API. | J10: Public responses contain only allowed fields | L10: Not started
A11: X05 | B11: API | C11: Limit page size and tighten rate limits | D11: Big pages + a generous limit make bulk copying of the whole catalogue easy. | E11: Cap ?limit at 20–50 server-side. Stricter rate limit for logged-out requests (e.g. per IP per minute). Consider Cloudflare bot protection in front of /api/. | F11: ?limit=500 returned 104 items; limit is 10,000 requests / 15 min per IP. | G11: Should | H11: Medium | I11: Make sure the app's own requests stay well under the new limits (check the biggest page size the app asks for). | J11: limit capped; logged-out limit lower | L11: Not started
A12: X06 | B12: API | C12: Check CORS settings | D12: The API sends 'Access-Control-Allow-Credentials: true'. If it also allows any website origin, other sites could make requests using a logged-in user's session. | E12: Allow only https://bideo.in (and the admin domain) as origins; never reflect any origin together with credentials. | F12: Not checked / not visible from outside | G12: Should | H12: Medium | I12: Test the website and admin panel still log in and load after the change. | J12: Only own domains allowed | L12: Not started
A13: X07 | B13: Privacy | C13: Decide whether to inform affected creators | D13: Their contact details were public; they may already have been copied. Being open builds trust; DPDP Act has breach-notification duties. | E13: After the fix, decide with whoever handles legal/compliance. Short message: what was exposed, that it's fixed, to be careful with unknown calls/messages. | F13: Not checked / not visible from outside | G13: Should | H13: Low | I13: — | J13: Decision recorded | L13: Not started
A14: X08 | B14: Security | C14: Add API security checks to every release | D14: Stops the same leak coming back with a new feature. | E14: Automated test per public endpoint: call it logged-out and fail the build if fields like phone, email, password, token, revenue appear. | F14: Not checked / not visible from outside | G14: Should | H14: Low | I14: — | J14: Test runs on every release | L14: Not started

Sheet 1. Foundations
A1: 1. Foundations — measurement + safety net (start here)
A2: Set these up before changing anything. They show whether Google can see you and protect the working system.
A4: ID | B4: Area | C4: Task | D4: Why it matters | E4: How to do it | F4: Current status (checked 7 Oct 2026) | G4: Priority | H4: Break risk | I4: How to do it safely (don't break anything) | J4: Done when… | K4: Owner | L4: Status
A5: A. Measurement (do these first — free)
A6: F01 | B6: Google | C6: Verify bideo.in in Google Search Console (Domain property) | D6: It's the only way to see whether Google has indexed your pages, which errors it found, and what people search to find you. It also lets you submit your sitemap and ask Google to index pages. | E6: search.google.com/search-console → Add property → Domain → add the TXT record it gives you at your domain registrar (DNS). | F6: PROBLEM — bideo.in does not show on Google. The site's homepage file is dated 4 Oct 2026, so Google may simply not know about it yet. | G6: Must | H6: Low | I6: Adding a DNS TXT record does not touch the website. Do NOT edit or delete any other DNS record while you are there. | J6: Property verified; data starts showing | L6: Not started
A7: F02 | B7: Google | C7: Submit sitemap + request indexing | D7: Tells Google exactly which pages exist instead of waiting for it to find them. | E7: Search Console → Sitemaps → submit https://bideo.in/sitemap.xml. Then URL Inspection → homepage → 'Request indexing'. Repeat for ~10 best video pages. | F7: OK — sitemap.xml exists with video tags, robots.txt points to it. | G7: Must | H7: Low | I7: Read-only for your site. | J7: Sitemap status 'Success'; homepage 'URL is on Google' | L7: Not started
A8: F03 | B8: Bing | C8: Bing Webmaster Tools | D8: Bing powers results in Bing, DuckDuckGo, Yahoo, and is one of the search sources used by ChatGPT search and Microsoft Copilot — important for AEO. | E8: bing.com/webmasters → 'Import from Google Search Console' (fastest) → submit sitemap. | F8: Not set up (assumed) | G8: Must | H8: Low | I8: Read-only for your site. | J8: Site verified in Bing; sitemap processed | L8: Not started
A9: F04 | B9: Bing | C9: IndexNow — instant notice when a new video is published | D9: New videos get discovered by Bing (and Yandex, Seznam) within minutes instead of days. | E9: Generate a key, host the key file, and have the backend send a ping to api.indexnow.org with the new URL after each publish/delete. | F9: Not set up (assumed) | G9: Should | H9: Low | I9: Send the ping in the background after publishing; if it fails, just log it — never block the upload. | J9: New video URLs appear in Bing within a day | L9: Not started
A10: F05 | B10: Analytics | C10: Google Analytics 4 on the website + link to Search Console | D10: Shows which pages bring visitors and how many click 'Download app'. | E10: Add GA4 tag; track 'download_app_click' events; link GA4 ↔ Search Console. | F10: Not checked / not visible from outside | G10: Should | H10: Low | I10: Load the tag async; test the page still loads normally. | J10: Visits and download clicks visible in GA4 | L10: Not started
A11: F06 | B11: Baseline | C11: Write down today's numbers before changing anything | D11: Without a 'before' you can't prove what improved — or quickly notice if a change broke something. | E11: Fill the first row of the 'Monthly Tracker' tab: indexed pages, impressions, Play visitors, installs, rating, crash rate. | F11: Known today: Play 10K+ downloads, rating 4.7. | G11: Must | H11: Low | I11: — | J11: Baseline row filled | L11: Not started
A12: B. Safety net (needed because of 'don't break anything')
A13: F07 | B13: Safety | C13: Staging copy of the website | D13: Every SEO change (redirects, rendering, 404s) should be tried on a copy first. Testing on the live site is how working systems break. | E13: e.g. staging.bideo.in with the same nginx config and build. Block it from Google with password/basic-auth (not just robots). | F13: Not checked / not visible from outside | G13: Must | H13: Low | I13: Make sure staging has noindex/password and production does NOT — this mix-up is a common disaster. | J13: Staging works and is not public | L13: Not started
A14: F08 | B14: Safety | C14: Backups + one-command rollback | D14: If a change breaks the site, you must be able to go back in minutes. | E14: Before each change: copy nginx config, keep the previous website build folder, tag the git commit. Write the rollback steps down. | F14: Not checked / not visible from outside | G14: Must | H14: Low | I14: — | J14: Rollback tested once on staging | L14: Not started
A15: F09 | B15: Safety | C15: Uptime monitoring | D15: Tells you within minutes if the site, a video page or the API goes down after a change. | E15: Free tools (e.g. UptimeRobot / Better Stack): monitor /, one /v/ page, /sitemap.xml, and the API health endpoint. | F15: Not checked / not visible from outside | G15: Should | H15: Low | I15: — | J15: Alerts reach your phone/email | L15: Not started

Sheet 2. Technical SEO
A1: 2. Technical SEO — can search engines read the website?
A2: Most of the reasons bideo.in doesn't appear on Google are here. Section A lists real problems found on the live site.
A4: ID | B4: Area | C4: Task | D4: Why it matters | E4: How to do it | F4: Current status (checked 7 Oct 2026) | G4: Priority | H4: Break risk | I4: How to do it safely (don't break anything) | J4: Done when… | K4: Owner | L4: Status
A5: A. Problems found on the live site (fix first)
A6: T01 | B6: Rendering | C6: Make the homepage and main pages send real content in the HTML | D6: Today Google receives an empty page and must run JavaScript to see anything. Google does that slowly and not always; Bing and most AI crawlers often don't run JavaScript at all — so to them Bideo has no content. | E6: The site is a Vite + React app. Easiest safe route: pre-render (generate HTML at build time) for /, /about, /creators, /faq, /download, /privacy, /terms. Bigger route later: server-side rendering (SSR) for all public pages. | F6: PROBLEM — homepage HTML is only a title, a description and an empty <div id="root">. | G6: Must | H6: Medium | I6: Pre-render only public pages; leave login/upload/admin as they are. Test on staging that the page looks the same and buttons still work before going live. | J6: 'View source' of the homepage shows the real text | L6: Not started
A7: T02 | B7: Robots | C7: Stop robots.txt from blocking the data pages need | D7: robots.txt says 'Disallow: /api/', but the website loads its videos, users and categories from /api/. When Google renders a page it obeys robots.txt, so it can't load that data → it sees empty pages. | E7: KEEP 'Disallow: /api/' — do NOT open the API to crawlers (it currently exposes creators' phone numbers/emails, see Security tab). Fix it the other way: server-render / pre-render the public pages (T01) so the content is already in the HTML and no API call is needed to read it. | F7: PROBLEM — robots.txt blocks /api/; the site's JavaScript calls /api/videos, /api/users, /api/categories. (Corrected 7 Oct: earlier version of this sheet suggested allowing /api/videos — don't.) | G7: Must | H7: Low | I7: Do the Security tab fixes first. Leave robots.txt as it is. After T01, test with Search Console → URL Inspection → 'Test live URL' → screenshot. | J7: Live test screenshot shows real videos with /api/ still blocked | L7: Not started
A8: T03 | B8: Redirects | C8: Redirect www.bideo.in → bideo.in (301) | D8: Two addresses serving the same site splits Google's signals between them and creates duplicate content. | E8: nginx: a server block for www.bideo.in that returns 301 to https://bideo.in$request_uri. | F8: PROBLEM — https://www.bideo.in/ returns 200 (the same site), not a redirect. | G8: Must | H8: Low | I8: Keep $request_uri so every path still works. Run 'nginx -t' before 'nginx -s reload'. Don't touch other subdomains (API, media). | J8: www URLs return 301 to the same path on bideo.in | L8: Not started
A9: T04 | B9: 404s | C9: Return a real 404 for pages that don't exist | D9: Right now any made-up address returns 200 + the homepage. Google calls these 'soft 404s', wastes crawl time on them, and may index junk addresses. | E9: Serve index.html only for known routes (/, /v/*, /c/*, /p/*, /about…); everything else → 404 page. For /v/<id> where the video doesn't exist or was deleted → 404 (or 410). | F9: PROBLEM — /this-page-does-not-exist-xyz returns 200 with the homepage. | G9: Must | H9: Medium | I9: List every route the website uses first (including login, upload, admin). Test each on staging. A missed route would 404 for real users. | J9: Unknown URLs return 404; all real pages still 200 | L9: Not started
A10: T05 | B10: Video page | C10: Remove the automatic jump to the app on video pages | D10: Video pages run a script that, on any Android phone, immediately sends the visitor to the app/Play Store. Google's mobile crawler identifies itself as an Android phone, so it can be sent away before reading the page. Users who wanted to watch on the web also leave. | E10: Remove the automatic window.location.replace(...). Show a clear 'Open in app' button instead. Android App Links (assetlinks.json already exists) open the app automatically when someone taps a bideo.in link from WhatsApp etc. | F10: PROBLEM — /v/ pages auto-redirect Android visitors to intent://… / Play Store. | G10: Must | H10: Medium | I10: Test on a real Android phone: (1) WhatsApp link still opens the app; (2) with the app uninstalled, the page shows the video and a 'Get the app' button. | J10: Video pages show content on Android; links still open the app | L10: Not started
A11: T06 | B11: Pages | C11: Make /privacy and /terms real pages | D11: Google Play, Meta and Google Ads review these URLs. Today they return the empty homepage shell, so to any crawler/reviewer they are blank. | E11: Pre-render them (see first task) or serve them as plain HTML. | F11: PROBLEM — /privacy and /terms return exactly the same HTML as the homepage. | G11: Must | H11: Low | I11: Plain extra pages; no effect on the rest of the site. | J11: View source shows the policy text | L11: Not started
A12: T07 | B12: Speed | C12: Turn on compression (gzip / brotli) | D12: The main JavaScript file is ~564 KB and is sent uncompressed. Compression typically shrinks it to ~25–35% → much faster loading on Indian mobile networks; speed is a ranking factor. | E12: nginx: 'gzip on;' with gzip_types for text/css, application/javascript, application/json, image/svg+xml, application/xml. Add brotli if the module is available. | F12: PROBLEM — /assets/index-…js served without Content-Encoding (≈564 KB). | G12: Must | H12: Low | I12: 'nginx -t' then reload. Check pages and video playback still work (don't compress video files). | J12: JS response shows Content-Encoding: gzip/br | L12: Not started
A13: T08 | B13: Sitemap | C13: Check whether the sitemap is capped | D13: If only a fixed number of pages are listed, Google may never find the rest of your videos. | E13: Look at the sitemap code. Use a sitemap index: sitemap-videos-1.xml, sitemap-creators.xml, sitemap-pages.xml… (max 50,000 URLs per file). Add accurate <lastmod>. | F13: PROBLEM? — sitemap has exactly 1,000 /v/, 200 /c/ and 200 /p/ URLs — looks like hard limits. | G13: Should | H13: Low | I13: Keep the same URL https://bideo.in/sitemap.xml (make it the index), so Search Console keeps working. | J13: All public videos/creators are in the sitemaps | L13: Not started
A14: B. Core technical health
A15: T09 | B15: Speed | C15: Core Web Vitals on mobile | D15: Google uses page experience signals; slow pages also lose visitors. | E15: Check pagespeed.web.dev for /, a /v/ page and a /c/ page. Targets: LCP < 2.5s, INP < 200ms, CLS < 0.1. Usual fixes: smaller JS (code-splitting), fixed image sizes, preload the main thumbnail, fewer fonts. | F15: Not checked / not visible from outside | G15: Should | H15: Medium | I15: Change one thing at a time; compare scores before/after on staging. | J15: All 3 page types 'Good' on mobile | L15: Not started
A16: T10 | B16: Speed | C16: Cache headers | D16: Repeat visitors and crawlers load faster; less server load. | E16: Files in /assets/ (hashed names): Cache-Control 'public, max-age=31536000, immutable'. HTML: short cache or no-cache. | F16: Not checked / not visible from outside | G16: Should | H16: Medium | I16: NEVER long-cache index.html or HTML pages — users would be stuck on an old version. | J16: Headers verified with curl -I | L16: Not started
A17: T11 | B17: Canonical | C17: Canonical tag on every public page | D17: Tells Google which address is the 'real' one (stops duplicates from ?utm=… or www). | E17: <link rel="canonical" href="https://bideo.in/<path>"> on home, creator, post, category and static pages. | F17: OK on video pages; missing on homepage. | G17: Should | H17: Low | I17: Canonical must point to the page itself (never all to the homepage). | J17: Every page has a self-canonical | L17: Not started
A18: T12 | B18: Links | C18: Real links between pages | D18: Google discovers pages by following <a href> links. Clicks handled only by JavaScript (onClick) are invisible to it. | E18: Video cards, creator names, categories, 'related videos' → real <a href="/v/…"> links. | F18: Not checked / not visible from outside | G18: Should | H18: Low | I18: Keeps the same look; just changes the element type. Test clicks still work. | J18: Links visible in page source | L18: Not started
A19: T13 | B19: Security | C19: HTTPS + HSTS | D19: HTTPS is a ranking signal and required for trust. | E19: http → https already redirects. Add 'Strict-Transport-Security' header starting with a short max-age (e.g. 1 day), increase later. | F19: OK — http://bideo.in → 301 to https. | G19: Nice | H19: Medium | I19: HSTS is hard to undo; start short and only after all subdomains are on HTTPS. | J19: Header present | L19: Not started
A20: T14 | B20: Language | C20: Correct language tag | D20: Helps Google show pages to people searching in that language. | E20: Set <html lang> to the page's language (e.g. 'hi' for Hindi videos). If you later make full Hindi versions of pages, add hreflang tags. | F20: Site uses lang="en" while much content is Hindi. | G20: Nice | H20: Low | I20: — | J20: lang matches content | L20: Not started
A21: T15 | B21: Monitoring | C21: Fix errors in Search Console every week | D21: 'Page indexing' and 'Core Web Vitals' reports list exactly what's wrong. | E21: Weekly 15 min: check new errors, fix, click 'Validate fix'. | F21: — | G21: Must | H21: Low | I21: — | J21: No new errors for 4 weeks | L21: Not started

Sheet 3. Pages & Content
A1: 3. Pages & Content — what the website says
A2: Pages and text that rank, build trust and answer what people search.
A4: ID | B4: Area | C4: Task | D4: Why it matters | E4: How to do it | F4: Current status (checked 7 Oct 2026) | G4: Priority | H4: Break risk | I4: How to do it safely (don't break anything) | J4: Done when… | K4: Owner | L4: Status
A5: A. Pages every serious app website needs
A6: C01 | B6: Homepage | C6: Rewrite the homepage with real content | D6: It's the page that must rank for 'Bideo' and explain the app to Google, AI engines and people. | E6: H1 with what Bideo is (e.g. 'Bideo – watch and create short videos in Hindi & Indian languages'); 3–5 sections: for viewers, for creators (how they grow/earn), trending videos (real links), FAQ, 'Get it on Google Play' button. | F6: PROBLEM — empty in HTML (see Technical T01). | G6: Must | H6: Medium | I6: Build it on staging; keep existing app features and links working. | J6: Homepage text visible in page source | L6: Not started
A7: C02 | B7: Titles | C7: Unique title + meta description for every page type | D7: The title is the blue link in Google results; the description is the grey text. Good ones get more clicks. | E7: Templates — Video: '<video title> | <creator> on Bideo'. Creator: '<Name> (@handle) – Videos on Bideo'. Home: 'Bideo – Short Video App for India | Watch, Create, Grow'. Titles ≤ ~60 chars, descriptions ~150 chars. | F7: Video pages OK (title = video title). Creator page shows 'Bideo on Bideo - Bideo'. | G7: Must | H7: Low | I7: Text-only change in templates. | J7: No duplicate titles in Search Console | L7: Not started
A8: C03 | B8: Static pages | C8: About, For Creators, Download, FAQ, Contact | D8: Builds trust with Google (who runs this, how to contact), answers what people search, and gives AI engines facts to quote. | E8: About: who is behind Bideo, mission, launch date, city. For Creators: how to start, how earning works. Download: Play link + QR. Contact: email. | F8: Not checked / not visible from outside | G8: Must | H8: Low | I8: New pages only. | J8: All pages live and linked in the footer | L8: Not started
A9: C04 | B9: Policy pages | C9: Privacy, Terms, Community guidelines, Copyright/takedown, Account deletion | D9: Required by Google Play and ad platforms; trust signal for search. | E9: Each as its own real HTML page; link them in the footer and in the Play listing. | F9: /privacy and /terms exist only as JS (see T06). | G9: Must | H9: Low | I9: — | J9: All pages readable without JavaScript | L9: Not started
A10: C05 | B10: Social preview | C10: Open Graph image for homepage & static pages | D10: Controls how links look when shared on WhatsApp, Instagram, X, LinkedIn — more clicks. | E10: og:title, og:description, og:image (1200×630), twitter:card. | F10: OK on video pages; homepage missing. | G10: Should | H10: Low | I10: — | J10: Previews look right in WhatsApp | L10: Not started
A11: B. Pages that bring search traffic (after A)
A12: C06 | B12: Hub pages | C12: Category and language pages | D12: People search 'Hindi comedy videos', 'Bhojpuri songs short video' — hub pages can rank for these and link to many videos. | E12: /category/comedy, /hindi, /hindi/comedy … with a short intro text and a list of the best videos (real links). Create only where there are enough videos (e.g. 20+). | F12: Categories exist in the app (/api/categories). | G12: Should | H12: Low | I12: Don't create empty or near-empty pages — Google treats them as thin content. | J12: Hub pages indexed and getting impressions | L12: Not started
A13: C07 | B13: Hub pages | C13: Trending / New pages | D13: Fresh pages that change daily get crawled often and help new videos get found fast. | E13: /trending and /new with real links to videos. | F13: Not checked / not visible from outside | G13: Nice | H13: Low | I13: — | J13: Pages crawled daily (see Search Console crawl stats) | L13: Not started
A14: C08 | B14: Blog | C14: Creator guides (blog) | D14: Ranks for creator questions ('how to earn from short videos in India', 'how to make AI videos') and brings creators — your supply side. AI engines quote such guides. | E14: 1–2 helpful articles a month, in Hindi and English, written from real experience. Each links to sign-up. | F14: Not checked / not visible from outside | G14: Nice | H14: Low | I14: — | J14: Articles ranking for target questions | L14: Not started
A15: C09 | B15: Brand text | C15: One fixed brand description everywhere | D15: Search engines and AI engines trust facts that match across the web. | E15: Write one 1-sentence and one 3-sentence description of Bideo. Use the same wording on the site, Play Store, social profiles and directories. | F15: Different wording today (site: 'modern video platform for India'; Play: 'short videos… grow your community'). | G15: Must | H15: Low | I15: — | J15: Same description on all profiles | L15: Not started
A16: C10 | B16: Images | C16: Alt text and file names | D16: Image search traffic and accessibility. | E16: Alt = video title / creator name; descriptive file names for site images. | F16: Not checked / not visible from outside | G16: Nice | H16: Low | I16: — | J16: Images have alt text | L16: Not started

Sheet 4. Video & Creator Pages
A1: 4. Video & Creator Pages — your biggest SEO opportunity
A2: Thousands of video and creator pages can each bring search traffic — if Google can read them.
A4: ID | B4: Area | C4: Task | D4: Why it matters | E4: How to do it | F4: Current status (checked 7 Oct 2026) | G4: Priority | H4: Break risk | I4: How to do it safely (don't break anything) | J4: Done when… | K4: Owner | L4: Status
A5: A. Video pages (/v/…) — your biggest SEO asset
A6: V01 | B6: Schema | C6: VideoObject structured data on every video page | D6: Lets Google show your videos in video results with thumbnail, duration and date — a big source of free traffic. | E6: JSON-LD with name, description, thumbnailUrl, uploadDate (required), plus duration, contentUrl, embedUrl, interactionStatistic (views), author. Test with Google's Rich Results Test. | F6: PROBLEM — no JSON-LD on video pages. | G6: Must | H6: Low | I6: Added in <head>; doesn't change what users see. Validate before deploying. | J6: Search Console → 'Videos' report shows indexed videos | L6: Not started
A7: V02 | B7: Content | C7: Visible text on the video page | D7: Right now the page has a title and almost no text. Google needs words to understand and rank it. | E7: Show in HTML: title, description, creator name (linked), upload date, views, category, hashtags, and 6–12 'related videos' links. Later: transcript. | F7: PROBLEM — page body is mostly scripts. | G7: Must | H7: Medium | I7: Same as the video page design in the app; build on staging. | J7: Text visible in page source | L7: Not started
A8: V03 | B8: Player | C8: Video must play on the web page itself | D8: Google only indexes a video when it's the main thing on its page and can be played there. | E8: A web player on /v/ pages (with an 'Open in app' button next to it). | F8: PROBLEM — page pushes Android users to the app (see T05). | G8: Must | H8: Medium | I8: Keep the app link flow working (test on Android). | J8: Video plays in a desktop & mobile browser | L8: Not started
A9: V04 | B9: Titles | C9: Better video titles & descriptions | D9: Titles become Google results. 'Bideo app pr ai se video bnakar dal skte h' is hard to search for; clear titles in proper Hindi/English rank better. | E9: Done inside the app at upload (see 'Inside the App' tab): required title, suggested format, description field. | F9: Example found: title and description identical, informal spelling. | G9: Must | H9: Low | I9: — | J9: New uploads have a proper title + different description | L9: Not started
A10: V05 | B10: Quality | C10: Keep low-quality videos out of Google | D10: Hundreds of near-empty pages can lower how Google sees the whole site. | E10: Add 'noindex' and leave out of the sitemap: videos with no title, very short clips, private/unlisted, removed or reported content. | F10: Not checked / not visible from outside | G10: Should | H10: Low | I10: Only affects the excluded pages. | J10: Rules applied in code | L10: Not started
A11: V06 | B11: Removed | C11: Deleted videos return 404/410 and leave the sitemap | D11: Stops Google from showing dead pages and wasting crawl time. | E11: Backend: if the video doesn't exist → 404 (or 410). | F11: Related to T04 (soft 404s). | G11: Must | H11: Low | I11: — | J11: Deleted video URL returns 404 | L11: Not started
A12: V07 | B12: Sitemap | C12: Complete video sitemap fields | D12: More data helps Google index videos. | E12: Add <video:duration>, <video:publication_date>; keep title, description, thumbnail and content_loc (already there). | F12: OK — thumbnail, title, description, content_loc present. | G12: Should | H12: Low | I12: — | J12: Sitemap validates in Search Console | L12: Not started
A13: V08 | B13: Media | C13: Serve videos/thumbnails from your own domain | D13: Files are on a 'pub-…r2.dev' address. Cloudflare says r2.dev links are rate-limited and meant for development, not production. Your own domain is also more trustworthy and stable. | E13: Connect a custom domain to the R2 bucket (e.g. media.bideo.in) and use it for new URLs. | F13: PROBLEM — media served from pub-…r2.dev. | G13: Should | H13: Medium | I13: Keep old r2.dev URLs working while switching; switch new uploads first, then old ones gradually. | J13: New media URLs on media.bideo.in | L13: Not started
A14: V09 | B14: Embeds | C14: Embed player for other websites | D14: Each embed on another site is a link and a mention of Bideo → authority + AI visibility. | E14: /embed/<id> page + 'Embed' option on the share menu. | F14: Not checked / not visible from outside | G14: Nice | H14: Low | I14: — | J14: Embed works on a test page | L14: Not started
A15: B. Creator (/c/) and post (/p/) pages
A16: V10 | B16: Creator | C16: Proper creator page titles and content | D16: People search creators by name. A good creator page can rank for '<creator name>'. | E16: Title '<Name> (@handle) – Videos on Bideo', bio, follower count, list of videos with real links, ProfilePage + Person JSON-LD. | F16: PROBLEM — creator page title 'Bideo on Bideo - Bideo'. | G16: Must | H16: Low | I16: Template change only. | J16: Creator pages show name in title | L16: Not started
A17: V11 | B17: Posts | C17: Same treatment for /p/ pages | D17: Each public post is a potential search result. | E17: Title, description, canonical, OG image, real text in HTML. | F17: Not checked / not visible from outside | G17: Should | H17: Low | I17: — | J17: Post pages render text in HTML | L17: Not started

Sheet 5. AEO (AI Search)
A1: 5. AEO — get mentioned by ChatGPT, Perplexity, Gemini, Copilot & Google AI Overviews
A2: AI engines answer from pages they can read and facts they see repeated across trusted sites.
A4: ID | B4: Area | C4: Task | D4: Why it matters | E4: How to do it | F4: Current status (checked 7 Oct 2026) | G4: Priority | H4: Break risk | I4: How to do it safely (don't break anything) | J4: Done when… | K4: Owner | L4: Status
A5: A. Let AI engines read you
A6: A01 | B6: Crawlers | C6: Allow AI search crawlers | D6: ChatGPT, Perplexity, Claude, Gemini and Copilot can only mention what their crawlers can read. | E6: Keep robots.txt open to: Googlebot, Bingbot, OAI-SearchBot, ChatGPT-User, GPTBot, PerplexityBot, ClaudeBot, Claude-SearchBot, Applebot. Also check Cloudflare/hosting 'block AI bots' settings are OFF. | F6: OK — robots.txt allows all bots (except /api/, /admin/). | G6: Must | H6: Low | I6: Don't block them by mistake when editing robots.txt. | J6: All listed bots allowed | L6: Not started
A7: A02 | B7: Rendering | C7: Content readable without JavaScript | D7: Most AI crawlers don't run JavaScript. Today they see an empty Bideo homepage. | E7: Same fix as Technical T01/T02. | F7: PROBLEM — see T01. | G7: Must | H7: Medium | I7: See T01. | J7: View source shows text | L7: Not started
A8: A03 | B8: Bing | C8: Be indexed in Bing | D8: ChatGPT search and Copilot use Bing among their sources. | E8: See Foundations F03 (+ IndexNow). | F8: Not set up (assumed) | G8: Must | H8: Low | I8: — | J8: Pages indexed in Bing | L8: Not started
A9: A04 | B9: llms.txt | C9: Add /llms.txt (optional) | D9: A proposed standard — a short plain-text summary of your site for AI tools. Google doesn't use it; some AI tools do. Cheap to add. | E9: Plain-text file at /llms.txt: what Bideo is, key pages (about, creators, FAQ, download), contact. | F9: PROBLEM — /llms.txt returns the homepage HTML (file doesn't exist). | G9: Nice | H9: Low | I9: Make sure nginx serves it as text/plain, not the app shell. | J9: File returns text/plain | L9: Not started
A10: B. Give AI engines clear facts to quote
A11: A05 | B11: Answer | C11: 'What is Bideo?' answer at the top of homepage & About | D11: AI engines quote short, clear, factual paragraphs. | E11: 2–3 sentences: what it is, for whom, which languages, free or paid, who runs it, since when. | F11: Not checked / not visible from outside | G11: Must | H11: Low | I11: — | J11: Paragraph live on both pages | L11: Not started
A12: A06 | B12: FAQ | C12: FAQ page with real questions | D12: People ask AI 'Is Bideo safe?', 'How do I earn on Bideo?', 'Bideo vs Moj/YouTube Shorts?'. A clear answer on your site is what gets quoted. | E12: 10–20 questions from user support, Play reviews and search terms. Short direct answers. Note: Google now shows FAQ rich results only for government/health sites, so don't expect stars — this is for AI answers and users. | F12: Not checked / not visible from outside | G12: Must | H12: Low | I12: — | J12: FAQ live and linked from footer | L12: Not started
A13: A07 | B13: Schema | C13: Organization + WebSite + MobileApplication structured data | D13: Tells machines exactly who you are and links your profiles together (a step toward a Google knowledge panel). | E13: Homepage JSON-LD: Organization (name, url, logo, description, sameAs: Play Store, Instagram, YouTube, X, LinkedIn); WebSite; MobileApplication (name, operatingSystem ANDROID, applicationCategory, offers price 0, download URL). | F13: PROBLEM — no structured data on homepage. | G13: Must | H13: Low | I13: Validate in Rich Results Test / schema.org validator. Don't copy Play Store ratings into your schema. | J13: Validator shows no errors | L13: Not started
A14: A08 | B14: Consistency | C14: Same facts everywhere | D14: AI engines cross-check: name, description, founder, launch year, category must match across site, Play, socials and directories. | E14: Use the brand text from Pages C09 everywhere. Fix differences. | F14: Different descriptions on site vs Play today. | G14: Must | H14: Low | I14: — | J14: Facts match on all profiles | L14: Not started
A15: A09 | B15: Comparison | C15: Comparison & 'best apps' content | D15: Questions like 'best short video apps in India' are answered from list articles. Being on those lists (and having your own honest comparison page) gets you mentioned. | E15: Own page: 'Bideo vs other short video apps' (honest). Outreach to list-article writers (see Authority tab). | F15: Not checked / not visible from outside | G15: Should | H15: Low | I15: — | J15: Bideo appears in 3+ third-party lists | L15: Not started
A16: A10 | B16: Freshness | C16: Show dates and keep facts current | D16: AI engines prefer recent, dated information. | E16: 'Last updated' on key pages; update numbers (creators, videos, languages) monthly. | F16: Not checked / not visible from outside | G16: Nice | H16: Low | I16: — | J16: Dates visible | L16: Not started
A17: A11 | B17: Tracking | C17: Check AI visibility every month | D17: There's no Search Console for AI; you have to ask. | E17: Each month ask ChatGPT, Perplexity, Gemini and Copilot the same 10 prompts (list in Monthly Tracker tab). Record how many mention Bideo. | F17: Not checked / not visible from outside | G17: Should | H17: Low | I17: — | J17: Score recorded monthly | L17: Not started

Sheet 6. ASO - Google Play
A1: 6. ASO — Google Play Store
A2: How to rank in Play Store search and turn store visitors into installs.
A4: ID | B4: Area | C4: Task | D4: Why it matters | E4: How to do it | F4: Current status (checked 7 Oct 2026) | G4: Priority | H4: Break risk | I4: How to do it safely (don't break anything) | J4: Done when… | K4: Owner | L4: Status
A5: A. Store listing text (what Play Store search reads)
A6: G01 | B6: Research | C6: Keyword research | D6: You can only rank for words people actually search. Guessing wastes your 30 + 80 + 4,000 characters. | E6: Sources: Play Console → Statistics → acquisition by search term; Play Store search autocomplete (type 'short video', 'video app hindi'…); competitor listings (Moj, Josh, Chingari, YouTube, etc.). Pick 5–10 main keywords. | F6: Not checked / not visible from outside | G6: Must | H6: Low | I6: — | J6: Keyword list agreed | L6: Not started
A7: G02 | B7: Title | C7: App title (max 30 characters) | D7: The title is the strongest ranking signal on Play. Today it's only 'Bideo' — 25 characters of free keywords are unused. | E7: Brand + main keyword, e.g. 'Bideo: Short Video App India' (28). Not allowed: emojis, ALL CAPS, words like 'best', '#1', 'free', 'top', or ranking claims. | F7: PROBLEM — title is just 'Bideo'. | G7: Must | H7: Low | I7: Text-only change, reviewed by Google before going live. Keep 'Bideo' first so existing users still find it. | J7: New title live | L7: Not started
A8: G03 | B8: Short desc | C8: Short description (max 80 characters) | D8: Shown under the title and indexed for search; it's the main sales line. | E8: Main benefit + 1–2 keywords, e.g. 'Watch & create short videos in Hindi and Indian languages. Grow as a creator.' | F8: Current: 'Watch, create & share short videos. Discover creators and grow your community.' — generic, no language/India keywords. | G8: Must | H8: Low | I8: Same as above. | J8: New short description live | L8: Not started
A9: G04 | B9: Full desc | C9: Full description (max 4,000 characters) | D9: Play indexes it. First 3 lines show before 'more' — they must sell. | E9: Opening lines = benefit; then features for viewers, for creators, languages, safety. Use main keywords naturally ~3–5 times each. No keyword lists, no fake testimonials (policy). | F9: Not checked / not visible from outside | G9: Must | H9: Low | I9: Avoid keyword stuffing — it can get the listing rejected. | J9: New description live | L9: Not started
A10: G05 | B10: Developer | C10: Developer name & contact | D10: Shown on the listing; a brand/company name builds trust. | E10: Use a brand or company name as developer name; real support email; website = https://bideo.in; privacy policy URL that actually shows text. | F10: Package id is com.farhan.bideoapp — this can NEVER be changed (a new id = a new app). | G10: Should | H10: Low | I10: Do NOT try to change the package name. | J10: Details updated | L10: Not started
A11: B. Graphics (what makes people tap Install)
A12: G06 | B12: Icon | C12: Icon 512×512 | D12: First thing people see in search results; strongly affects tap rate. | E12: Simple, bold, readable at small size. Test 2 versions with Store listing experiments. | F12: Not checked / not visible from outside | G12: Should | H12: Low | I12: Test with an experiment, not by switching blindly. | J12: Winning icon live | L12: Not started
A13: G07 | B13: Screenshots | C13: 4–8 phone screenshots with captions | D13: Most people decide from the first 2–3 screenshots without reading text. | E13: Screenshot 1 = main benefit; each with a short caption in large text; show real content; versions in Hindi for Hindi listing. | F13: Not checked / not visible from outside | G13: Must | H13: Low | I13: — | J13: New set live | L13: Not started
A14: G08 | B14: Feature graphic | C14: Feature graphic 1024×500 | D14: Required for featuring and shown with the promo video. | E14: Brand + one line + phone mockup; no tiny text. | F14: Not checked / not visible from outside | G14: Must | H14: Low | I14: — | J14: Uploaded | L14: Not started
A15: G09 | B15: Video | C15: Promo video (YouTube link, ~30s) | D15: Shows the app in action; raises installs for many apps. | E15: Real app footage, first 5s strongest, subtitles. | F15: Not checked / not visible from outside | G15: Should | H15: Low | I15: — | J15: Video live on listing | L15: Not started
A16: C. Reach & testing
A17: G10 | B17: Languages | C17: Localised listings (Hindi + target languages) | D17: Ranks for searches typed in those languages and converts better. | E17: Play Console → Main store listing → Manage translations → add Hindi (and others) with your own translations and translated screenshots. | F17: Not checked / not visible from outside | G17: Should | H17: Low | I17: — | J17: Hindi listing live | L17: Not started
A18: G11 | B18: Category | C18: Category & tags | D18: Decides which charts and 'similar apps' you appear in. | E18: Compare 'Video Players & Editors' vs 'Entertainment' vs 'Social' by competitors there; set Store tags in Play Console. | F18: Not checked / not visible from outside | G18: Should | H18: Low | I18: Change category rarely; note the date in the change log. | J18: Category + tags reviewed | L18: Not started
A19: G12 | B19: Experiments | C19: Store listing experiments (A/B tests) | D19: Lets Google show two versions and tells you which gets more installs — no guessing. | E19: Test one thing at a time: icon → screenshots → short description. Run until Play shows a result. | F19: Not checked / not visible from outside | G19: Should | H19: Low | I19: Only one experiment at a time. | J19: 2 experiments completed | L19: Not started
A20: G13 | B20: Custom listings | C20: Custom store listings | D20: Different pages for ads/countries/languages convert better. | E20: Play Console → Custom store listings (e.g. one for Hindi ads). | F20: Not checked / not visible from outside | G20: Nice | H20: Low | I20: — | J20: 1 custom listing live | L20: Not started
A21: G14 | B21: Events | C21: Promotional content (LiveOps) | D21: Events and offers show on the store and in search; can bring back users. | E21: Play Console → Promotional content → e.g. creator contest, festival event. | F21: Not checked / not visible from outside | G21: Nice | H21: Low | I21: — | J21: 1 event run | L21: Not started
A22: D. Quality signals Play uses for ranking
A23: G15 | B23: Ratings | C23: Ratings & reviews | D23: Rating and recent reviews affect both ranking and tap-through. | E23: In-App Review API at a happy moment (see Inside the App tab). Reply to every review within 48h, especially negative ones. | F23: OK — rating 4.7. | G23: Must | H23: Low | I23: Never buy or incentivise reviews (Play policy). | J23: All reviews answered; rating ≥ 4.5 | L23: Not started
A24: G16 | B24: Vitals | C24: Android vitals: crash & ANR rates | D24: Above Play's 'bad behaviour' thresholds (user-perceived crash rate 1.09%, ANR rate 0.47%) Play can lower your visibility and show warnings on the listing. | E24: Play Console → Android vitals weekly; fix top crashes/ANRs first. | F24: Not checked / not visible from outside | G24: Must | H24: Low | I24: — | J24: Both rates well under thresholds | L24: Not started
A25: G17 | B25: Policy | C25: Data safety, content rating, privacy URL correct | D25: Wrong or missing declarations can get the app removed — the worst ASO outcome. | E25: Review Data safety form and content rating (user-generated content) whenever features change. | F25: Not checked / not visible from outside | G25: Must | H25: Low | I25: — | J25: Declarations match the app | L25: Not started
A26: G18 | B26: Updates | C26: Regular updates | D26: Active apps are trusted more by users and Play. | E26: Release every 2–4 weeks with clear 'What's new' text. | F26: Not checked / not visible from outside | G26: Nice | H26: Low | I26: Use staged rollouts (e.g. 10% → 50% → 100%) so a bad build doesn't hit everyone. | J26: Update cadence kept | L26: Not started

Sheet 7. ASO - App Store
A1: 7. ASO — Apple App Store (only if/when an iPhone app launches)
A2: Skip this tab until there's an iOS app; mark tasks 'Not needed' for now.
A4: ID | B4: Area | C4: Task | D4: Why it matters | E4: How to do it | F4: Current status (checked 7 Oct 2026) | G4: Priority | H4: Break risk | I4: How to do it safely (don't break anything) | J4: Done when… | K4: Owner | L4: Status
A5: Only when/if the iPhone app is launched
A6: I01 | B6: Text | C6: App name (30), subtitle (30), keyword field (100) | D6: On the App Store these 3 fields carry almost all search weight; the description is NOT used for search. | E6: Keyword field: comma-separated, no spaces, don't repeat words already in name/subtitle, singular forms. | F6: No iOS app seen. | G6: Must | H6: Low | I6: — | J6: Fields filled | L6: Not started
A7: I02 | B7: Text | C7: Promotional text (170) & description | D7: Promotional text can be changed without an update — use for events. | E7: Same benefit-first structure as Play. | F7: — | G7: Should | H7: Low | I7: — | J7: Done | L7: Not started
A8: I03 | B8: Graphics | C8: Screenshots & app preview videos | D8: Same reason as Play — decides installs. | E8: Up to 10 screenshots; up to 3 preview videos (≤30s). | F8: — | G8: Must | H8: Low | I8: — | J8: Done | L8: Not started
